WARNING 2025-06-06 16:27:25,162 log 9760 5048 Not Found: /favicon.ico
WARNING 2025-06-06 19:09:12,773 log 14092 10448 Not Found: /favicon.ico
WARNING 2025-06-07 01:27:51,373 log 14288 4268 Not Found: /favicon.ico
WARNING 2025-06-07 13:23:10,109 log 11504 10040 Not Found: /favicon.ico
WARNING 2025-06-07 13:54:12,703 log 14884 3844 Not Found: /admin
WARNING 2025-06-07 13:54:21,629 log 14884 5484 Not Found: /admin
WARNING 2025-06-07 13:54:55,495 log 14884 7596 Not Found: /admin
WARNING 2025-06-07 13:57:19,729 log 6272 5092 Not Found: /favicon.ico
WARNING 2025-06-07 13:57:26,526 log 6272 9124 Not Found: /admin
WARNING 2025-06-07 13:57:29,667 log 6272 9124 Not Found: /admin
WARNING 2025-06-07 15:29:59,486 log 2520 14112 Not Found: /admin
WARNING 2025-06-07 15:30:00,118 log 2520 14112 Not Found: /favicon.ico
WARNING 2025-06-08 12:15:24,939 log 10112 3172 Not Found: /favicon.ico
ERROR 2025-06-08 13:33:19,589 log 12648 1816 Internal Server Error: /admin/users/customuser/add/
Traceback (most recent call last):
  File "C:\Users\kenc\website\env\Lib\site-packages\django\db\backends\base\base.py", line 303, in _commit
    return self.connection.commit()
           ~~~~~~~~~~~~~~~~~~~~~~^^
sqlite3.IntegrityError: FOREIGN KEY constraint failed

The above exception was the direct cause of the following exception:

Traceback (most recent call last):
  File "C:\Users\kenc\website\env\Lib\site-packages\django\core\handlers\exception.py", line 55, in inner
    response = get_response(request)
  File "C:\Users\kenc\website\env\Lib\site-packages\django\core\handlers\base.py", line 197, in _get_response
    response = wrapped_callback(request, *callback_args, **callback_kwargs)
  File "C:\Users\kenc\website\env\Lib\site-packages\django\contrib\admin\options.py", line 719, in wrapper
    return self.admin_site.admin_view(view)(*args, **kwargs)
           ~~~~~~~~~~~~~~~~~~~~~~~~~~~~~~~~^^^^^^^^^^^^^^^^^
  File "C:\Users\kenc\website\env\Lib\site-packages\django\utils\decorators.py", line 192, in _view_wrapper
    result = _process_exception(request, e)
  File "C:\Users\kenc\website\env\Lib\site-packages\django\utils\decorators.py", line 190, in _view_wrapper
    response = view_func(request, *args, **kwargs)
  File "C:\Users\kenc\website\env\Lib\site-packages\django\views\decorators\cache.py", line 80, in _view_wrapper
    response = view_func(request, *args, **kwargs)
  File "C:\Users\kenc\website\env\Lib\site-packages\django\contrib\admin\sites.py", line 246, in inner
    return view(request, *args, **kwargs)
  File "C:\Users\kenc\website\env\Lib\site-packages\django\utils\decorators.py", line 48, in _wrapper
    return bound_method(*args, **kwargs)
  File "C:\Users\kenc\website\env\Lib\site-packages\django\views\decorators\debug.py", line 143, in sensitive_post_parameters_wrapper
    return view(request, *args, **kwargs)
  File "C:\Users\kenc\website\env\Lib\site-packages\django\utils\decorators.py", line 48, in _wrapper
    return bound_method(*args, **kwargs)
  File "C:\Users\kenc\website\env\Lib\site-packages\django\utils\decorators.py", line 192, in _view_wrapper
    result = _process_exception(request, e)
  File "C:\Users\kenc\website\env\Lib\site-packages\django\utils\decorators.py", line 190, in _view_wrapper
    response = view_func(request, *args, **kwargs)
  File "C:\Users\kenc\website\env\Lib\site-packages\django\contrib\auth\admin.py", line 123, in add_view
    with transaction.atomic(using=router.db_for_write(self.model)):
         ~~~~~~~~~~~~~~~~~~^^^^^^^^^^^^^^^^^^^^^^^^^^^^^^^^^^^^^^^
  File "C:\Users\kenc\website\env\Lib\site-packages\django\db\transaction.py", line 263, in __exit__
    connection.commit()
    ~~~~~~~~~~~~~~~~~^^
  File "C:\Users\kenc\website\env\Lib\site-packages\django\utils\asyncio.py", line 26, in inner
    return func(*args, **kwargs)
  File "C:\Users\kenc\website\env\Lib\site-packages\django\db\backends\base\base.py", line 327, in commit
    self._commit()
    ~~~~~~~~~~~~^^
  File "C:\Users\kenc\website\env\Lib\site-packages\django\db\backends\base\base.py", line 302, in _commit
    with debug_transaction(self, "COMMIT"), self.wrap_database_errors:
                                            ^^^^^^^^^^^^^^^^^^^^^^^^^
  File "C:\Users\kenc\website\env\Lib\site-packages\django\db\utils.py", line 91, in __exit__
    raise dj_exc_value.with_traceback(traceback) from exc_value
  File "C:\Users\kenc\website\env\Lib\site-packages\django\db\backends\base\base.py", line 303, in _commit
    return self.connection.commit()
           ~~~~~~~~~~~~~~~~~~~~~~^^
django.db.utils.IntegrityError: FOREIGN KEY constraint failed
ERROR 2025-06-08 13:47:01,111 log 13004 13684 Internal Server Error: /admin/users/customuser/add/
Traceback (most recent call last):
  File "C:\Users\kenc\website\env\Lib\site-packages\django\db\backends\base\base.py", line 303, in _commit
    return self.connection.commit()
           ~~~~~~~~~~~~~~~~~~~~~~^^
sqlite3.IntegrityError: FOREIGN KEY constraint failed

The above exception was the direct cause of the following exception:

Traceback (most recent call last):
  File "C:\Users\kenc\website\env\Lib\site-packages\django\core\handlers\exception.py", line 55, in inner
    response = get_response(request)
  File "C:\Users\kenc\website\env\Lib\site-packages\django\core\handlers\base.py", line 197, in _get_response
    response = wrapped_callback(request, *callback_args, **callback_kwargs)
  File "C:\Users\kenc\website\env\Lib\site-packages\django\contrib\admin\options.py", line 719, in wrapper
    return self.admin_site.admin_view(view)(*args, **kwargs)
           ~~~~~~~~~~~~~~~~~~~~~~~~~~~~~~~~^^^^^^^^^^^^^^^^^
  File "C:\Users\kenc\website\env\Lib\site-packages\django\utils\decorators.py", line 192, in _view_wrapper
    result = _process_exception(request, e)
  File "C:\Users\kenc\website\env\Lib\site-packages\django\utils\decorators.py", line 190, in _view_wrapper
    response = view_func(request, *args, **kwargs)
  File "C:\Users\kenc\website\env\Lib\site-packages\django\views\decorators\cache.py", line 80, in _view_wrapper
    response = view_func(request, *args, **kwargs)
  File "C:\Users\kenc\website\env\Lib\site-packages\django\contrib\admin\sites.py", line 246, in inner
    return view(request, *args, **kwargs)
  File "C:\Users\kenc\website\env\Lib\site-packages\django\utils\decorators.py", line 48, in _wrapper
    return bound_method(*args, **kwargs)
  File "C:\Users\kenc\website\env\Lib\site-packages\django\views\decorators\debug.py", line 143, in sensitive_post_parameters_wrapper
    return view(request, *args, **kwargs)
  File "C:\Users\kenc\website\env\Lib\site-packages\django\utils\decorators.py", line 48, in _wrapper
    return bound_method(*args, **kwargs)
  File "C:\Users\kenc\website\env\Lib\site-packages\django\utils\decorators.py", line 192, in _view_wrapper
    result = _process_exception(request, e)
  File "C:\Users\kenc\website\env\Lib\site-packages\django\utils\decorators.py", line 190, in _view_wrapper
    response = view_func(request, *args, **kwargs)
  File "C:\Users\kenc\website\env\Lib\site-packages\django\contrib\auth\admin.py", line 123, in add_view
    with transaction.atomic(using=router.db_for_write(self.model)):
         ~~~~~~~~~~~~~~~~~~^^^^^^^^^^^^^^^^^^^^^^^^^^^^^^^^^^^^^^^
  File "C:\Users\kenc\website\env\Lib\site-packages\django\db\transaction.py", line 263, in __exit__
    connection.commit()
    ~~~~~~~~~~~~~~~~~^^
  File "C:\Users\kenc\website\env\Lib\site-packages\django\utils\asyncio.py", line 26, in inner
    return func(*args, **kwargs)
  File "C:\Users\kenc\website\env\Lib\site-packages\django\db\backends\base\base.py", line 327, in commit
    self._commit()
    ~~~~~~~~~~~~^^
  File "C:\Users\kenc\website\env\Lib\site-packages\django\db\backends\base\base.py", line 302, in _commit
    with debug_transaction(self, "COMMIT"), self.wrap_database_errors:
                                            ^^^^^^^^^^^^^^^^^^^^^^^^^
  File "C:\Users\kenc\website\env\Lib\site-packages\django\db\utils.py", line 91, in __exit__
    raise dj_exc_value.with_traceback(traceback) from exc_value
  File "C:\Users\kenc\website\env\Lib\site-packages\django\db\backends\base\base.py", line 303, in _commit
    return self.connection.commit()
           ~~~~~~~~~~~~~~~~~~~~~~^^
django.db.utils.IntegrityError: FOREIGN KEY constraint failed
ERROR 2025-06-08 13:47:46,433 log 13004 11668 Internal Server Error: /admin/users/customuser/add/
Traceback (most recent call last):
  File "C:\Users\kenc\website\env\Lib\site-packages\django\db\backends\base\base.py", line 303, in _commit
    return self.connection.commit()
           ~~~~~~~~~~~~~~~~~~~~~~^^
sqlite3.IntegrityError: FOREIGN KEY constraint failed

The above exception was the direct cause of the following exception:

Traceback (most recent call last):
  File "C:\Users\kenc\website\env\Lib\site-packages\django\core\handlers\exception.py", line 55, in inner
    response = get_response(request)
  File "C:\Users\kenc\website\env\Lib\site-packages\django\core\handlers\base.py", line 197, in _get_response
    response = wrapped_callback(request, *callback_args, **callback_kwargs)
  File "C:\Users\kenc\website\env\Lib\site-packages\django\contrib\admin\options.py", line 719, in wrapper
    return self.admin_site.admin_view(view)(*args, **kwargs)
           ~~~~~~~~~~~~~~~~~~~~~~~~~~~~~~~~^^^^^^^^^^^^^^^^^
  File "C:\Users\kenc\website\env\Lib\site-packages\django\utils\decorators.py", line 192, in _view_wrapper
    result = _process_exception(request, e)
  File "C:\Users\kenc\website\env\Lib\site-packages\django\utils\decorators.py", line 190, in _view_wrapper
    response = view_func(request, *args, **kwargs)
  File "C:\Users\kenc\website\env\Lib\site-packages\django\views\decorators\cache.py", line 80, in _view_wrapper
    response = view_func(request, *args, **kwargs)
  File "C:\Users\kenc\website\env\Lib\site-packages\django\contrib\admin\sites.py", line 246, in inner
    return view(request, *args, **kwargs)
  File "C:\Users\kenc\website\env\Lib\site-packages\django\utils\decorators.py", line 48, in _wrapper
    return bound_method(*args, **kwargs)
  File "C:\Users\kenc\website\env\Lib\site-packages\django\views\decorators\debug.py", line 143, in sensitive_post_parameters_wrapper
    return view(request, *args, **kwargs)
  File "C:\Users\kenc\website\env\Lib\site-packages\django\utils\decorators.py", line 48, in _wrapper
    return bound_method(*args, **kwargs)
  File "C:\Users\kenc\website\env\Lib\site-packages\django\utils\decorators.py", line 192, in _view_wrapper
    result = _process_exception(request, e)
  File "C:\Users\kenc\website\env\Lib\site-packages\django\utils\decorators.py", line 190, in _view_wrapper
    response = view_func(request, *args, **kwargs)
  File "C:\Users\kenc\website\env\Lib\site-packages\django\contrib\auth\admin.py", line 123, in add_view
    with transaction.atomic(using=router.db_for_write(self.model)):
         ~~~~~~~~~~~~~~~~~~^^^^^^^^^^^^^^^^^^^^^^^^^^^^^^^^^^^^^^^
  File "C:\Users\kenc\website\env\Lib\site-packages\django\db\transaction.py", line 263, in __exit__
    connection.commit()
    ~~~~~~~~~~~~~~~~~^^
  File "C:\Users\kenc\website\env\Lib\site-packages\django\utils\asyncio.py", line 26, in inner
    return func(*args, **kwargs)
  File "C:\Users\kenc\website\env\Lib\site-packages\django\db\backends\base\base.py", line 327, in commit
    self._commit()
    ~~~~~~~~~~~~^^
  File "C:\Users\kenc\website\env\Lib\site-packages\django\db\backends\base\base.py", line 302, in _commit
    with debug_transaction(self, "COMMIT"), self.wrap_database_errors:
                                            ^^^^^^^^^^^^^^^^^^^^^^^^^
  File "C:\Users\kenc\website\env\Lib\site-packages\django\db\utils.py", line 91, in __exit__
    raise dj_exc_value.with_traceback(traceback) from exc_value
  File "C:\Users\kenc\website\env\Lib\site-packages\django\db\backends\base\base.py", line 303, in _commit
    return self.connection.commit()
           ~~~~~~~~~~~~~~~~~~~~~~^^
django.db.utils.IntegrityError: FOREIGN KEY constraint failed
ERROR 2025-06-08 13:55:45,549 log 1796 13672 Internal Server Error: /admin/users/customuser/add/
Traceback (most recent call last):
  File "C:\Users\kenc\website\env\Lib\site-packages\django\db\backends\base\base.py", line 303, in _commit
    return self.connection.commit()
           ~~~~~~~~~~~~~~~~~~~~~~^^
sqlite3.IntegrityError: FOREIGN KEY constraint failed

The above exception was the direct cause of the following exception:

Traceback (most recent call last):
  File "C:\Users\kenc\website\env\Lib\site-packages\django\core\handlers\exception.py", line 55, in inner
    response = get_response(request)
  File "C:\Users\kenc\website\env\Lib\site-packages\django\core\handlers\base.py", line 197, in _get_response
    response = wrapped_callback(request, *callback_args, **callback_kwargs)
  File "C:\Users\kenc\website\env\Lib\site-packages\django\contrib\admin\options.py", line 719, in wrapper
    return self.admin_site.admin_view(view)(*args, **kwargs)
           ~~~~~~~~~~~~~~~~~~~~~~~~~~~~~~~~^^^^^^^^^^^^^^^^^
  File "C:\Users\kenc\website\env\Lib\site-packages\django\utils\decorators.py", line 192, in _view_wrapper
    result = _process_exception(request, e)
  File "C:\Users\kenc\website\env\Lib\site-packages\django\utils\decorators.py", line 190, in _view_wrapper
    response = view_func(request, *args, **kwargs)
  File "C:\Users\kenc\website\env\Lib\site-packages\django\views\decorators\cache.py", line 80, in _view_wrapper
    response = view_func(request, *args, **kwargs)
  File "C:\Users\kenc\website\env\Lib\site-packages\django\contrib\admin\sites.py", line 246, in inner
    return view(request, *args, **kwargs)
  File "C:\Users\kenc\website\env\Lib\site-packages\django\utils\decorators.py", line 48, in _wrapper
    return bound_method(*args, **kwargs)
  File "C:\Users\kenc\website\env\Lib\site-packages\django\views\decorators\debug.py", line 143, in sensitive_post_parameters_wrapper
    return view(request, *args, **kwargs)
  File "C:\Users\kenc\website\env\Lib\site-packages\django\utils\decorators.py", line 48, in _wrapper
    return bound_method(*args, **kwargs)
  File "C:\Users\kenc\website\env\Lib\site-packages\django\utils\decorators.py", line 192, in _view_wrapper
    result = _process_exception(request, e)
  File "C:\Users\kenc\website\env\Lib\site-packages\django\utils\decorators.py", line 190, in _view_wrapper
    response = view_func(request, *args, **kwargs)
  File "C:\Users\kenc\website\env\Lib\site-packages\django\contrib\auth\admin.py", line 123, in add_view
    with transaction.atomic(using=router.db_for_write(self.model)):
         ~~~~~~~~~~~~~~~~~~^^^^^^^^^^^^^^^^^^^^^^^^^^^^^^^^^^^^^^^
  File "C:\Users\kenc\website\env\Lib\site-packages\django\db\transaction.py", line 263, in __exit__
    connection.commit()
    ~~~~~~~~~~~~~~~~~^^
  File "C:\Users\kenc\website\env\Lib\site-packages\django\utils\asyncio.py", line 26, in inner
    return func(*args, **kwargs)
  File "C:\Users\kenc\website\env\Lib\site-packages\django\db\backends\base\base.py", line 327, in commit
    self._commit()
    ~~~~~~~~~~~~^^
  File "C:\Users\kenc\website\env\Lib\site-packages\django\db\backends\base\base.py", line 302, in _commit
    with debug_transaction(self, "COMMIT"), self.wrap_database_errors:
                                            ^^^^^^^^^^^^^^^^^^^^^^^^^
  File "C:\Users\kenc\website\env\Lib\site-packages\django\db\utils.py", line 91, in __exit__
    raise dj_exc_value.with_traceback(traceback) from exc_value
  File "C:\Users\kenc\website\env\Lib\site-packages\django\db\backends\base\base.py", line 303, in _commit
    return self.connection.commit()
           ~~~~~~~~~~~~~~~~~~~~~~^^
django.db.utils.IntegrityError: FOREIGN KEY constraint failed
ERROR 2025-06-08 13:58:24,168 log 1796 14068 Internal Server Error: /admin/users/customuser/add/
Traceback (most recent call last):
  File "C:\Users\kenc\website\env\Lib\site-packages\django\db\backends\base\base.py", line 303, in _commit
    return self.connection.commit()
           ~~~~~~~~~~~~~~~~~~~~~~^^
sqlite3.IntegrityError: FOREIGN KEY constraint failed

The above exception was the direct cause of the following exception:

Traceback (most recent call last):
  File "C:\Users\kenc\website\env\Lib\site-packages\django\core\handlers\exception.py", line 55, in inner
    response = get_response(request)
  File "C:\Users\kenc\website\env\Lib\site-packages\django\core\handlers\base.py", line 197, in _get_response
    response = wrapped_callback(request, *callback_args, **callback_kwargs)
  File "C:\Users\kenc\website\env\Lib\site-packages\django\contrib\admin\options.py", line 719, in wrapper
    return self.admin_site.admin_view(view)(*args, **kwargs)
           ~~~~~~~~~~~~~~~~~~~~~~~~~~~~~~~~^^^^^^^^^^^^^^^^^
  File "C:\Users\kenc\website\env\Lib\site-packages\django\utils\decorators.py", line 192, in _view_wrapper
    result = _process_exception(request, e)
  File "C:\Users\kenc\website\env\Lib\site-packages\django\utils\decorators.py", line 190, in _view_wrapper
    response = view_func(request, *args, **kwargs)
  File "C:\Users\kenc\website\env\Lib\site-packages\django\views\decorators\cache.py", line 80, in _view_wrapper
    response = view_func(request, *args, **kwargs)
  File "C:\Users\kenc\website\env\Lib\site-packages\django\contrib\admin\sites.py", line 246, in inner
    return view(request, *args, **kwargs)
  File "C:\Users\kenc\website\env\Lib\site-packages\django\utils\decorators.py", line 48, in _wrapper
    return bound_method(*args, **kwargs)
  File "C:\Users\kenc\website\env\Lib\site-packages\django\views\decorators\debug.py", line 143, in sensitive_post_parameters_wrapper
    return view(request, *args, **kwargs)
  File "C:\Users\kenc\website\env\Lib\site-packages\django\utils\decorators.py", line 48, in _wrapper
    return bound_method(*args, **kwargs)
  File "C:\Users\kenc\website\env\Lib\site-packages\django\utils\decorators.py", line 192, in _view_wrapper
    result = _process_exception(request, e)
  File "C:\Users\kenc\website\env\Lib\site-packages\django\utils\decorators.py", line 190, in _view_wrapper
    response = view_func(request, *args, **kwargs)
  File "C:\Users\kenc\website\env\Lib\site-packages\django\contrib\auth\admin.py", line 123, in add_view
    with transaction.atomic(using=router.db_for_write(self.model)):
         ~~~~~~~~~~~~~~~~~~^^^^^^^^^^^^^^^^^^^^^^^^^^^^^^^^^^^^^^^
  File "C:\Users\kenc\website\env\Lib\site-packages\django\db\transaction.py", line 263, in __exit__
    connection.commit()
    ~~~~~~~~~~~~~~~~~^^
  File "C:\Users\kenc\website\env\Lib\site-packages\django\utils\asyncio.py", line 26, in inner
    return func(*args, **kwargs)
  File "C:\Users\kenc\website\env\Lib\site-packages\django\db\backends\base\base.py", line 327, in commit
    self._commit()
    ~~~~~~~~~~~~^^
  File "C:\Users\kenc\website\env\Lib\site-packages\django\db\backends\base\base.py", line 302, in _commit
    with debug_transaction(self, "COMMIT"), self.wrap_database_errors:
                                            ^^^^^^^^^^^^^^^^^^^^^^^^^
  File "C:\Users\kenc\website\env\Lib\site-packages\django\db\utils.py", line 91, in __exit__
    raise dj_exc_value.with_traceback(traceback) from exc_value
  File "C:\Users\kenc\website\env\Lib\site-packages\django\db\backends\base\base.py", line 303, in _commit
    return self.connection.commit()
           ~~~~~~~~~~~~~~~~~~~~~~^^
django.db.utils.IntegrityError: FOREIGN KEY constraint failed
ERROR 2025-06-08 13:59:54,582 log 5348 7348 Internal Server Error: /admin/users/customuser/add/
Traceback (most recent call last):
  File "C:\Users\kenc\website\env\Lib\site-packages\django\db\backends\base\base.py", line 303, in _commit
    return self.connection.commit()
           ~~~~~~~~~~~~~~~~~~~~~~^^
sqlite3.IntegrityError: FOREIGN KEY constraint failed

The above exception was the direct cause of the following exception:

Traceback (most recent call last):
  File "C:\Users\kenc\website\env\Lib\site-packages\django\core\handlers\exception.py", line 55, in inner
    response = get_response(request)
  File "C:\Users\kenc\website\env\Lib\site-packages\django\core\handlers\base.py", line 197, in _get_response
    response = wrapped_callback(request, *callback_args, **callback_kwargs)
  File "C:\Users\kenc\website\env\Lib\site-packages\django\contrib\admin\options.py", line 719, in wrapper
    return self.admin_site.admin_view(view)(*args, **kwargs)
           ~~~~~~~~~~~~~~~~~~~~~~~~~~~~~~~~^^^^^^^^^^^^^^^^^
  File "C:\Users\kenc\website\env\Lib\site-packages\django\utils\decorators.py", line 192, in _view_wrapper
    result = _process_exception(request, e)
  File "C:\Users\kenc\website\env\Lib\site-packages\django\utils\decorators.py", line 190, in _view_wrapper
    response = view_func(request, *args, **kwargs)
  File "C:\Users\kenc\website\env\Lib\site-packages\django\views\decorators\cache.py", line 80, in _view_wrapper
    response = view_func(request, *args, **kwargs)
  File "C:\Users\kenc\website\env\Lib\site-packages\django\contrib\admin\sites.py", line 246, in inner
    return view(request, *args, **kwargs)
  File "C:\Users\kenc\website\env\Lib\site-packages\django\utils\decorators.py", line 48, in _wrapper
    return bound_method(*args, **kwargs)
  File "C:\Users\kenc\website\env\Lib\site-packages\django\views\decorators\debug.py", line 143, in sensitive_post_parameters_wrapper
    return view(request, *args, **kwargs)
  File "C:\Users\kenc\website\env\Lib\site-packages\django\utils\decorators.py", line 48, in _wrapper
    return bound_method(*args, **kwargs)
  File "C:\Users\kenc\website\env\Lib\site-packages\django\utils\decorators.py", line 192, in _view_wrapper
    result = _process_exception(request, e)
  File "C:\Users\kenc\website\env\Lib\site-packages\django\utils\decorators.py", line 190, in _view_wrapper
    response = view_func(request, *args, **kwargs)
  File "C:\Users\kenc\website\env\Lib\site-packages\django\contrib\auth\admin.py", line 123, in add_view
    with transaction.atomic(using=router.db_for_write(self.model)):
         ~~~~~~~~~~~~~~~~~~^^^^^^^^^^^^^^^^^^^^^^^^^^^^^^^^^^^^^^^
  File "C:\Users\kenc\website\env\Lib\site-packages\django\db\transaction.py", line 263, in __exit__
    connection.commit()
    ~~~~~~~~~~~~~~~~~^^
  File "C:\Users\kenc\website\env\Lib\site-packages\django\utils\asyncio.py", line 26, in inner
    return func(*args, **kwargs)
  File "C:\Users\kenc\website\env\Lib\site-packages\django\db\backends\base\base.py", line 327, in commit
    self._commit()
    ~~~~~~~~~~~~^^
  File "C:\Users\kenc\website\env\Lib\site-packages\django\db\backends\base\base.py", line 302, in _commit
    with debug_transaction(self, "COMMIT"), self.wrap_database_errors:
                                            ^^^^^^^^^^^^^^^^^^^^^^^^^
  File "C:\Users\kenc\website\env\Lib\site-packages\django\db\utils.py", line 91, in __exit__
    raise dj_exc_value.with_traceback(traceback) from exc_value
  File "C:\Users\kenc\website\env\Lib\site-packages\django\db\backends\base\base.py", line 303, in _commit
    return self.connection.commit()
           ~~~~~~~~~~~~~~~~~~~~~~^^
django.db.utils.IntegrityError: FOREIGN KEY constraint failed
ERROR 2025-06-08 14:01:29,543 log 5348 8540 Internal Server Error: /admin/enquiry/enquiry/add/
Traceback (most recent call last):
  File "C:\Users\kenc\website\env\Lib\site-packages\django\db\backends\base\base.py", line 303, in _commit
    return self.connection.commit()
           ~~~~~~~~~~~~~~~~~~~~~~^^
sqlite3.IntegrityError: FOREIGN KEY constraint failed

The above exception was the direct cause of the following exception:

Traceback (most recent call last):
  File "C:\Users\kenc\website\env\Lib\site-packages\django\core\handlers\exception.py", line 55, in inner
    response = get_response(request)
  File "C:\Users\kenc\website\env\Lib\site-packages\django\core\handlers\base.py", line 197, in _get_response
    response = wrapped_callback(request, *callback_args, **callback_kwargs)
  File "C:\Users\kenc\website\env\Lib\site-packages\django\contrib\admin\options.py", line 719, in wrapper
    return self.admin_site.admin_view(view)(*args, **kwargs)
           ~~~~~~~~~~~~~~~~~~~~~~~~~~~~~~~~^^^^^^^^^^^^^^^^^
  File "C:\Users\kenc\website\env\Lib\site-packages\django\utils\decorators.py", line 192, in _view_wrapper
    result = _process_exception(request, e)
  File "C:\Users\kenc\website\env\Lib\site-packages\django\utils\decorators.py", line 190, in _view_wrapper
    response = view_func(request, *args, **kwargs)
  File "C:\Users\kenc\website\env\Lib\site-packages\django\views\decorators\cache.py", line 80, in _view_wrapper
    response = view_func(request, *args, **kwargs)
  File "C:\Users\kenc\website\env\Lib\site-packages\django\contrib\admin\sites.py", line 246, in inner
    return view(request, *args, **kwargs)
  File "C:\Users\kenc\website\env\Lib\site-packages\django\contrib\admin\options.py", line 1984, in add_view
    return self.changeform_view(request, None, form_url, extra_context)
           ~~~~~~~~~~~~~~~~~~~~^^^^^^^^^^^^^^^^^^^^^^^^^^^^^^^^^^^^^^^^
  File "C:\Users\kenc\website\env\Lib\site-packages\django\utils\decorators.py", line 48, in _wrapper
    return bound_method(*args, **kwargs)
  File "C:\Users\kenc\website\env\Lib\site-packages\django\utils\decorators.py", line 192, in _view_wrapper
    result = _process_exception(request, e)
  File "C:\Users\kenc\website\env\Lib\site-packages\django\utils\decorators.py", line 190, in _view_wrapper
    response = view_func(request, *args, **kwargs)
  File "C:\Users\kenc\website\env\Lib\site-packages\django\contrib\admin\options.py", line 1842, in changeform_view
    with transaction.atomic(using=router.db_for_write(self.model)):
         ~~~~~~~~~~~~~~~~~~^^^^^^^^^^^^^^^^^^^^^^^^^^^^^^^^^^^^^^^
  File "C:\Users\kenc\website\env\Lib\site-packages\django\db\transaction.py", line 263, in __exit__
    connection.commit()
    ~~~~~~~~~~~~~~~~~^^
  File "C:\Users\kenc\website\env\Lib\site-packages\django\utils\asyncio.py", line 26, in inner
    return func(*args, **kwargs)
  File "C:\Users\kenc\website\env\Lib\site-packages\django\db\backends\base\base.py", line 327, in commit
    self._commit()
    ~~~~~~~~~~~~^^
  File "C:\Users\kenc\website\env\Lib\site-packages\django\db\backends\base\base.py", line 302, in _commit
    with debug_transaction(self, "COMMIT"), self.wrap_database_errors:
                                            ^^^^^^^^^^^^^^^^^^^^^^^^^
  File "C:\Users\kenc\website\env\Lib\site-packages\django\db\utils.py", line 91, in __exit__
    raise dj_exc_value.with_traceback(traceback) from exc_value
  File "C:\Users\kenc\website\env\Lib\site-packages\django\db\backends\base\base.py", line 303, in _commit
    return self.connection.commit()
           ~~~~~~~~~~~~~~~~~~~~~~^^
django.db.utils.IntegrityError: FOREIGN KEY constraint failed
ERROR 2025-06-08 14:02:10,891 log 5348 4768 Internal Server Error: /admin/portfolio/project/add/
Traceback (most recent call last):
  File "C:\Users\kenc\website\env\Lib\site-packages\django\db\backends\base\base.py", line 303, in _commit
    return self.connection.commit()
           ~~~~~~~~~~~~~~~~~~~~~~^^
sqlite3.IntegrityError: FOREIGN KEY constraint failed

The above exception was the direct cause of the following exception:

Traceback (most recent call last):
  File "C:\Users\kenc\website\env\Lib\site-packages\django\core\handlers\exception.py", line 55, in inner
    response = get_response(request)
  File "C:\Users\kenc\website\env\Lib\site-packages\django\core\handlers\base.py", line 197, in _get_response
    response = wrapped_callback(request, *callback_args, **callback_kwargs)
  File "C:\Users\kenc\website\env\Lib\site-packages\django\contrib\admin\options.py", line 719, in wrapper
    return self.admin_site.admin_view(view)(*args, **kwargs)
           ~~~~~~~~~~~~~~~~~~~~~~~~~~~~~~~~^^^^^^^^^^^^^^^^^
  File "C:\Users\kenc\website\env\Lib\site-packages\django\utils\decorators.py", line 192, in _view_wrapper
    result = _process_exception(request, e)
  File "C:\Users\kenc\website\env\Lib\site-packages\django\utils\decorators.py", line 190, in _view_wrapper
    response = view_func(request, *args, **kwargs)
  File "C:\Users\kenc\website\env\Lib\site-packages\django\views\decorators\cache.py", line 80, in _view_wrapper
    response = view_func(request, *args, **kwargs)
  File "C:\Users\kenc\website\env\Lib\site-packages\django\contrib\admin\sites.py", line 246, in inner
    return view(request, *args, **kwargs)
  File "C:\Users\kenc\website\env\Lib\site-packages\django\contrib\admin\options.py", line 1984, in add_view
    return self.changeform_view(request, None, form_url, extra_context)
           ~~~~~~~~~~~~~~~~~~~~^^^^^^^^^^^^^^^^^^^^^^^^^^^^^^^^^^^^^^^^
  File "C:\Users\kenc\website\env\Lib\site-packages\django\utils\decorators.py", line 48, in _wrapper
    return bound_method(*args, **kwargs)
  File "C:\Users\kenc\website\env\Lib\site-packages\django\utils\decorators.py", line 192, in _view_wrapper
    result = _process_exception(request, e)
  File "C:\Users\kenc\website\env\Lib\site-packages\django\utils\decorators.py", line 190, in _view_wrapper
    response = view_func(request, *args, **kwargs)
  File "C:\Users\kenc\website\env\Lib\site-packages\django\contrib\admin\options.py", line 1842, in changeform_view
    with transaction.atomic(using=router.db_for_write(self.model)):
         ~~~~~~~~~~~~~~~~~~^^^^^^^^^^^^^^^^^^^^^^^^^^^^^^^^^^^^^^^
  File "C:\Users\kenc\website\env\Lib\site-packages\django\db\transaction.py", line 263, in __exit__
    connection.commit()
    ~~~~~~~~~~~~~~~~~^^
  File "C:\Users\kenc\website\env\Lib\site-packages\django\utils\asyncio.py", line 26, in inner
    return func(*args, **kwargs)
  File "C:\Users\kenc\website\env\Lib\site-packages\django\db\backends\base\base.py", line 327, in commit
    self._commit()
    ~~~~~~~~~~~~^^
  File "C:\Users\kenc\website\env\Lib\site-packages\django\db\backends\base\base.py", line 302, in _commit
    with debug_transaction(self, "COMMIT"), self.wrap_database_errors:
                                            ^^^^^^^^^^^^^^^^^^^^^^^^^
  File "C:\Users\kenc\website\env\Lib\site-packages\django\db\utils.py", line 91, in __exit__
    raise dj_exc_value.with_traceback(traceback) from exc_value
  File "C:\Users\kenc\website\env\Lib\site-packages\django\db\backends\base\base.py", line 303, in _commit
    return self.connection.commit()
           ~~~~~~~~~~~~~~~~~~~~~~^^
django.db.utils.IntegrityError: FOREIGN KEY constraint failed
ERROR 2025-06-08 14:03:07,634 log 5348 10476 Internal Server Error: /admin/project_requests/projectrequest/add/
Traceback (most recent call last):
  File "C:\Users\kenc\website\env\Lib\site-packages\django\db\backends\base\base.py", line 303, in _commit
    return self.connection.commit()
           ~~~~~~~~~~~~~~~~~~~~~~^^
sqlite3.IntegrityError: FOREIGN KEY constraint failed

The above exception was the direct cause of the following exception:

Traceback (most recent call last):
  File "C:\Users\kenc\website\env\Lib\site-packages\django\core\handlers\exception.py", line 55, in inner
    response = get_response(request)
  File "C:\Users\kenc\website\env\Lib\site-packages\django\core\handlers\base.py", line 197, in _get_response
    response = wrapped_callback(request, *callback_args, **callback_kwargs)
  File "C:\Users\kenc\website\env\Lib\site-packages\django\contrib\admin\options.py", line 719, in wrapper
    return self.admin_site.admin_view(view)(*args, **kwargs)
           ~~~~~~~~~~~~~~~~~~~~~~~~~~~~~~~~^^^^^^^^^^^^^^^^^
  File "C:\Users\kenc\website\env\Lib\site-packages\django\utils\decorators.py", line 192, in _view_wrapper
    result = _process_exception(request, e)
  File "C:\Users\kenc\website\env\Lib\site-packages\django\utils\decorators.py", line 190, in _view_wrapper
    response = view_func(request, *args, **kwargs)
  File "C:\Users\kenc\website\env\Lib\site-packages\django\views\decorators\cache.py", line 80, in _view_wrapper
    response = view_func(request, *args, **kwargs)
  File "C:\Users\kenc\website\env\Lib\site-packages\django\contrib\admin\sites.py", line 246, in inner
    return view(request, *args, **kwargs)
  File "C:\Users\kenc\website\env\Lib\site-packages\django\contrib\admin\options.py", line 1984, in add_view
    return self.changeform_view(request, None, form_url, extra_context)
           ~~~~~~~~~~~~~~~~~~~~^^^^^^^^^^^^^^^^^^^^^^^^^^^^^^^^^^^^^^^^
  File "C:\Users\kenc\website\env\Lib\site-packages\django\utils\decorators.py", line 48, in _wrapper
    return bound_method(*args, **kwargs)
  File "C:\Users\kenc\website\env\Lib\site-packages\django\utils\decorators.py", line 192, in _view_wrapper
    result = _process_exception(request, e)
  File "C:\Users\kenc\website\env\Lib\site-packages\django\utils\decorators.py", line 190, in _view_wrapper
    response = view_func(request, *args, **kwargs)
  File "C:\Users\kenc\website\env\Lib\site-packages\django\contrib\admin\options.py", line 1842, in changeform_view
    with transaction.atomic(using=router.db_for_write(self.model)):
         ~~~~~~~~~~~~~~~~~~^^^^^^^^^^^^^^^^^^^^^^^^^^^^^^^^^^^^^^^
  File "C:\Users\kenc\website\env\Lib\site-packages\django\db\transaction.py", line 263, in __exit__
    connection.commit()
    ~~~~~~~~~~~~~~~~~^^
  File "C:\Users\kenc\website\env\Lib\site-packages\django\utils\asyncio.py", line 26, in inner
    return func(*args, **kwargs)
  File "C:\Users\kenc\website\env\Lib\site-packages\django\db\backends\base\base.py", line 327, in commit
    self._commit()
    ~~~~~~~~~~~~^^
  File "C:\Users\kenc\website\env\Lib\site-packages\django\db\backends\base\base.py", line 302, in _commit
    with debug_transaction(self, "COMMIT"), self.wrap_database_errors:
                                            ^^^^^^^^^^^^^^^^^^^^^^^^^
  File "C:\Users\kenc\website\env\Lib\site-packages\django\db\utils.py", line 91, in __exit__
    raise dj_exc_value.with_traceback(traceback) from exc_value
  File "C:\Users\kenc\website\env\Lib\site-packages\django\db\backends\base\base.py", line 303, in _commit
    return self.connection.commit()
           ~~~~~~~~~~~~~~~~~~~~~~^^
django.db.utils.IntegrityError: FOREIGN KEY constraint failed
WARNING 2025-06-08 15:37:05,890 log 8524 10568 Not Found: /favicon.ico
WARNING 2025-07-06 18:04:11,949 log 5900 5816 Not Found: /favicon.ico
WARNING 2025-07-06 18:17:31,233 log 5900 10320 Unauthorized: /api/blog/posts/
WARNING 2025-07-06 18:17:31,259 log 5900 10320 Unauthorized: /api/blog/posts/
WARNING 2025-07-06 18:17:56,349 log 5900 5608 Unauthorized: /api/blog/posts/
WARNING 2025-07-06 18:17:56,358 log 5900 5608 Unauthorized: /api/blog/posts/
WARNING 2025-07-06 18:17:59,868 log 5900 10020 Unauthorized: /api/blog/posts/
WARNING 2025-07-06 18:17:59,878 log 5900 10020 Unauthorized: /api/blog/posts/
WARNING 2025-07-06 18:18:05,692 log 5900 9828 Unauthorized: /api/blog/posts/
WARNING 2025-07-06 18:18:05,705 log 5900 9828 Unauthorized: /api/blog/posts/
WARNING 2025-07-06 18:18:43,393 log 5900 10356 Unauthorized: /api/blog/posts/
WARNING 2025-07-06 18:18:43,408 log 5900 7944 Unauthorized: /api/blog/posts/
WARNING 2025-07-06 18:18:44,429 log 5900 7944 Unauthorized: /api/blog/posts/
WARNING 2025-07-06 18:18:44,438 log 5900 7944 Unauthorized: /api/blog/posts/
WARNING 2025-07-06 18:18:45,302 log 5900 7944 Unauthorized: /api/blog/posts/
WARNING 2025-07-06 18:18:45,309 log 5900 7944 Unauthorized: /api/blog/posts/
WARNING 2025-07-06 18:18:46,097 log 5900 7944 Unauthorized: /api/blog/posts/
WARNING 2025-07-06 18:18:46,110 log 5900 7944 Unauthorized: /api/blog/posts/
WARNING 2025-07-06 18:18:46,915 log 5900 7944 Unauthorized: /api/blog/posts/
WARNING 2025-07-06 18:18:46,931 log 5900 7944 Unauthorized: /api/blog/posts/
WARNING 2025-07-06 18:18:47,733 log 5900 7944 Unauthorized: /api/blog/posts/
WARNING 2025-07-06 18:18:47,744 log 5900 7944 Unauthorized: /api/blog/posts/
WARNING 2025-07-06 18:18:48,824 log 5900 6372 Unauthorized: /api/blog/posts/
WARNING 2025-07-06 18:18:48,833 log 5900 6372 Unauthorized: /api/blog/posts/
WARNING 2025-07-06 18:18:49,650 log 5900 6372 Unauthorized: /api/blog/posts/
WARNING 2025-07-06 18:18:49,667 log 5900 6372 Unauthorized: /api/blog/posts/
WARNING 2025-07-06 18:21:35,580 log 5900 5668 Unauthorized: /api/blog/posts/
WARNING 2025-07-06 18:21:35,599 log 5900 5668 Unauthorized: /api/blog/posts/
WARNING 2025-07-06 18:21:38,933 log 5900 4044 Unauthorized: /api/blog/posts/
WARNING 2025-07-06 18:21:38,941 log 5900 4044 Unauthorized: /api/blog/posts/
WARNING 2025-07-06 18:21:47,634 log 5900 4044 Unauthorized: /api/blog/posts/
WARNING 2025-07-06 18:21:47,662 log 5900 4044 Unauthorized: /api/blog/posts/
WARNING 2025-07-06 18:22:31,869 log 5900 10544 Unauthorized: /api/blog/posts/
WARNING 2025-07-06 18:22:31,874 log 5900 10544 Unauthorized: /api/blog/posts/
WARNING 2025-07-06 18:22:35,803 log 5900 10544 Unauthorized: /api/blog/posts/
WARNING 2025-07-06 18:22:35,818 log 5900 10544 Unauthorized: /api/blog/posts/
